Time slot   0
ld_routine
	Loaded a process at input/proc/p0s, PID: 1 PRIO: 130
	CPU 2: Dispatched process  1
Time slot   1
Time slot   2
liballoc:218
print_pgtbl:
PID : 1
 PDG=7d3eb0006ac0 P4g=7d3eb4000c00 PUD=7d3eb4001c10 PMD=7d3eb4002c20
	Loaded a process at input/proc/m0s, PID: 2 PRIO: 120
	CPU 3: Dispatched process  2
	CPU 2: Put process  1 to run queue
	CPU 2: Dispatched process  1
Time slot   3
liballoc:218
print_pgtbl:
PID : 2
 PDG=7d3eb0008850 P4g=7d3ea8000c00 PUD=7d3ea8001c10 PMD=7d3ea8002c20
liballoc:218
print_pgtbl:
PID : 1
 PDG=7d3eb0006ac0 P4g=7d3eb4000c00 PUD=7d3eb4001c10 PMD=7d3eb4002c20
	Loaded a process at input/proc/s3, PID: 3 PRIO: 39
libfree:241
print_pgtbl:
PID : 1
 PDG=7d3eb0006ac0 P4g=7d3eb4000c00 PUD=7d3eb4001c10 PMD=7d3eb4002c20
Time slot   4
liballoc:218
print_pgtbl:
PID : 2
 PDG=7d3eb0008850 P4g=7d3ea8000c00 PUD=7d3ea8001c10 PMD=7d3ea8002c20
	CPU 1: Dispatched process  3
	CPU 3: Put process  2 to run queue
	CPU 3: Dispatched process  2
libfree:241
print_pgtbl:
PID : 2
 PDG=7d3eb0008850 P4g=7d3ea8000c00 PUD=7d3ea8001c10 PMD=7d3ea8002c20
Time slot   5
	CPU 2: Put process  1 to run queue
	CPU 2: Dispatched process  1
liballoc:218
print_pgtbl:
PID : 1
 PDG=7d3eb0006ac0 P4g=7d3eb4000c00 PUD=7d3eb4001c10 PMD=7d3eb4002c20
	Loaded a process at input/proc/s0, PID: 4 PRIO: 38
Time slot   6
	CPU 1: Put process  3 to run queue
	CPU 1: Dispatched process  4
	CPU 0: Dispatched process  3
liballoc:218
print_pgtbl:
PID : 2
 PDG=7d3eb0008850 P4g=7d3ea8000c00 PUD=7d3ea8001c10 PMD=7d3ea8002c20
libwrite:459
print_pgtbl:
PID : 1
 PDG=7d3eb0006ac0 P4g=7d3eb4000c00 PUD=7d3eb4001c10 PMD=7d3eb4002c20
	CPU 2: Put process  1 to run queue
	CPU 2: Dispatched process  1
libread:406
print_pgtbl:
PID : 1
 PDG=7d3eb0006ac0 P4g=7d3eb4000c00 PUD=7d3eb4001c10 PMD=7d3eb4002c20
Time slot   7
	CPU 3: Put process  2 to run queue
	CPU 3: Dispatched process  2
libwrite:459
print_pgtbl:
PID : 2
 PDG=7d3eb0008850 P4g=7d3ea8000c00 PUD=7d3ea8001c10 PMD=7d3ea8002c20
libwrite:459
print_pgtbl:
PID : 2
 PDG=7d3eb0008850 P4g=7d3ea8000c00 PUD=7d3ea8001c10 PMD=7d3ea8002c20
	CPU 1: Put process  4 to run queue
	CPU 1: Dispatched process  4
Time slot   8
	CPU 0: Put process  3 to run queue
	CPU 0: Dispatched process  3
	Loaded a process at input/proc/m1s, PID: 5 PRIO: 15
	CPU 3: Processed  2 has finished
	CPU 3: Dispatched process  5
	CPU 2: Put process  1 to run queue
liballoc:218
print_pgtbl:
PID : 5
 PDG=7d3eb000e320 P4g=7d3ea8004cf0 PUD=7d3ea8005d00 PMD=7d3ea8006d10
	CPU 2: Dispatched process  1
libread:406
print_pgtbl:
PID : 1
 PDG=7d3eb0006ac0 P4g=7d3eb4000c00 PUD=7d3eb4001c10 PMD=7d3eb4002c20
Time slot   9
liballoc:218
print_pgtbl:
PID : 5
 PDG=7d3eb000e320 P4g=7d3ea8004cf0 PUD=7d3ea8005d00 PMD=7d3ea8006d10
	CPU 1: Put process  4 to run queue
	CPU 1: Dispatched process  4
Time slot  10
	CPU 0: Put process  3 to run queue
	CPU 0: Dispatched process  3
	Loaded a process at input/proc/p1s, PID: 6 PRIO: 15
	CPU 3: Put process  5 to run queue
	CPU 3: Dispatched process  6
	CPU 2: Put process  1 to run queue
	CPU 2: Dispatched process  5
libfree:241
Time slot  11
print_pgtbl:
PID : 5
 PDG=7d3eb000e320 P4g=7d3ea8004cf0 PUD=7d3ea8005d00 PMD=7d3ea8006d10
	CPU 1: Put process  4 to run queue
	CPU 1: Dispatched process  4
Time slot  12
liballoc:218
print_pgtbl:
PID : 5
 PDG=7d3eb000e320 P4g=7d3ea8004cf0 PUD=7d3ea8005d00 PMD=7d3ea8006d10
	CPU 0: Put process  3 to run queue
	CPU 0: Dispatched process  3
	Loaded a process at input/proc/s2, PID: 7 PRIO: 120
	CPU 3: Put process  6 to run queue
	CPU 3: Dispatched process  6
	CPU 2: Put process  5 to run queue
	CPU 2: Dispatched process  5
libfree:241
print_pgtbl:
PID : 5
 PDG=7d3eb000e320 P4g=7d3ea8004cf0 PUD=7d3ea8005d00 PMD=7d3ea8006d10
Time slot  13
libfree:241
print_pgtbl:
PID : 5
 PDG=7d3eb000e320 P4g=7d3ea8004cf0 PUD=7d3ea8005d00 PMD=7d3ea8006d10
	CPU 1: Put process  4 to run queue
	CPU 1: Dispatched process  4
Time slot  14
	CPU 0: Put process  3 to run queue
	CPU 0: Dispatched process  3
	CPU 2: Processed  5 has finished
	CPU 2: Dispatched process  7
Time slot  15
	CPU 0: Processed  3 has finished
	CPU 3: Put process  6 to run queue
	CPU 3: Dispatched process  6
	CPU 0: Dispatched process  1
libread:406
print_pgtbl:
PID : 1
 PDG=7d3eb0006ac0 P4g=7d3eb4000c00 PUD=7d3eb4001c10 PMD=7d3eb4002c20
	Loaded a process at input/proc/s1, PID: 8 PRIO: 0
	CPU 1: Put process  4 to run queue
	CPU 1: Dispatched process  8
Time slot  16
	CPU 3: Put process  6 to run queue
	CPU 3: Dispatched process  6
Time slot  17
	CPU 0: Put process  1 to run queue
	CPU 0: Dispatched process  4
	CPU 2: Put process  7 to run queue
	CPU 2: Dispatched process  7
	CPU 1: Put process  8 to run queue
	CPU 1: Dispatched process  8
Time slot  18
	CPU 3: Put process  6 to run queue
	CPU 3: Dispatched process  6
	CPU 2: Put process  7 to run queue
	CPU 2: Dispatched process  7
Time slot  19
	CPU 0: Put process  4 to run queue
	CPU 0: Dispatched process  4
	CPU 1: Put process  8 to run queue
	CPU 1: Dispatched process  8
Time slot  20
	CPU 3: Processed  6 has finished
	CPU 3: Dispatched process  1
libfree:241
print_pgtbl:
PID : 1
 PDG=7d3eb0006ac0 P4g=7d3eb4000c00 PUD=7d3eb4001c10 PMD=7d3eb4002c20
	CPU 2: Put process  7 to run queue
	CPU 2: Dispatched process  7
Time slot  21
	CPU 0: Put process  4 to run queue
	CPU 0: Dispatched process  4
	CPU 1: Put process  8 to run queue
	CPU 1: Dispatched process  8
Time slot  22
	CPU 0: Processed  4 has finished
	CPU 0 stopped
	CPU 3: Processed  1 has finished
	CPU 3 stopped
	CPU 2: Put process  7 to run queue
	CPU 2: Dispatched process  7
Time slot  23
	CPU 1: Processed  8 has finished
	CPU 1 stopped
Time slot  24
Time slot  25
	CPU 2: Put process  7 to run queue
	CPU 2: Dispatched process  7
Time slot  26
Time slot  27
	CPU 2: Processed  7 has finished
	CPU 2 stopped
