Time slot   0
ld_routine
Time slot   1
	Loaded a process at input/proc/p0s, PID: 1 PRIO: 130
	CPU 1: Dispatched process  1
Time slot   2
liballoc:218
print_pgtbl:
PID : 1
 PDG=7f00b4006ac0 P4g=7f00b0000c00 PUD=7f00b0001c10 PMD=7f00b0002c20
	Loaded a process at input/proc/m0s, PID: 2 PRIO: 120
	CPU 2: Dispatched process  2
Time slot   3
liballoc:218
print_pgtbl:
PID : 2
 PDG=7f00b4008850 P4g=7f00a8000c00 PUD=7f00a8001c10 PMD=7f00a8002c20
	CPU 1: Put process  1 to run queue
	CPU 1: Dispatched process  1
liballoc:218
print_pgtbl:
PID : 1
 PDG=7f00b4006ac0 P4g=7f00b0000c00 PUD=7f00b0001c10 PMD=7f00b0002c20
Time slot   4
libfree:241
print_pgtbl:
PID : 1
 PDG=7f00b4006ac0 P4g=7f00b0000c00 PUD=7f00b0001c10 PMD=7f00b0002c20
liballoc:218
print_pgtbl:
PID : 2
 PDG=7f00b4008850 P4g=7f00a8000c00 PUD=7f00a8001c10 PMD=7f00a8002c20
	Loaded a process at input/proc/s1, PID: 3 PRIO: 0
	CPU 2: Put process  2 to run queue
	CPU 2: Dispatched process  3
Time slot   5
	CPU 3: Dispatched process  2
libfree:241
print_pgtbl:
PID : 2
 PDG=7f00b4008850 P4g=7f00a8000c00 PUD=7f00a8001c10 PMD=7f00a8002c20
	CPU 1: Put process  1 to run queue
	CPU 1: Dispatched process  1
liballoc:218
print_pgtbl:
PID : 1
 PDG=7f00b4006ac0 P4g=7f00b0000c00 PUD=7f00b0001c10 PMD=7f00b0002c20
liballoc:218
print_pgtbl:
PID : 2
 PDG=7f00b4008850 P4g=7f00a8000c00 PUD=7f00a8001c10 PMD=7f00a8002c20
libwrite:459
print_pgtbl:
PID : 1
 PDG=7f00b4006ac0 P4g=7f00b0000c00 PUD=7f00b0001c10 PMD=7f00b0002c20
Time slot   6
	Loaded a process at input/proc/p1s, PID: 4 PRIO: 15
	CPU 2: Put process  3 to run queue
	CPU 2: Dispatched process  3
Time slot   7
	CPU 3: Put process  2 to run queue
	CPU 3: Dispatched process  2
libwrite:459
print_pgtbl:
	CPU 1: Put process  1 to run queue
	CPU 1: Dispatched process  1
libread:406
print_pgtbl:
PID : 1
 PDG=7f00b4006ac0 P4g=7f00b0000c00 PUD=7f00b0001c10 PMD=7f00b0002c20
PID : 2
 PDG=7f00b4008850 P4g=7f00a8000c00 PUD=7f00a8001c10 PMD=7f00a8002c20
	CPU 0: Dispatched process  4
libwrite:459
print_pgtbl:
PID : 2
 PDG=7f00b4008850 P4g=7f00a8000c00 PUD=7f00a8001c10 PMD=7f00a8002c20
Time slot   8
	CPU 3: Processed  2 has finished
	Loaded a process at input/proc/s3, PID: 5 PRIO: 39
	CPU 2: Put process  3 to run queue
	CPU 2: Dispatched process  3
	CPU 1: Put process  1 to run queue
Time slot   9
	CPU 1: Dispatched process  5
	CPU 0: Put process  4 to run queue
	CPU 0: Dispatched process  4
	CPU 3: Dispatched process  1
libread:406
print_pgtbl:
PID : 1
 PDG=7f00b4006ac0 P4g=7f00b0000c00 PUD=7f00b0001c10 PMD=7f00b0002c20
Time slot  10
	Loaded a process at input/proc/s2, PID: 6 PRIO: 120
	CPU 2: Put process  3 to run queue
	CPU 2: Dispatched process  3
Time slot  11
	CPU 0: Put process  4 to run queue
	CPU 0: Dispatched process  4
	CPU 1: Put process  5 to run queue
	CPU 1: Dispatched process  5
	Loaded a process at input/proc/m1s, PID: 7 PRIO: 15
	CPU 3: Put process  1 to run queue
	CPU 3: Dispatched process  7
	CPU 2: Processed  3 has finished
	CPU 2: Dispatched process  6
liballoc:218
print_pgtbl:
PID : 7
 PDG=7f00b4011e90 P4g=7f00ac000c30 PUD=7f00ac001c40 PMD=7f00ac002c50
Time slot  12
	Loaded a process at input/proc/s0, PID: 8 PRIO: 38
liballoc:218
print_pgtbl:
PID : 7
 PDG=7f00b4011e90 P4g=7f00ac000c30 PUD=7f00ac001c40 PMD=7f00ac002c50
	CPU 1: Put process  5 to run queue
	CPU 1: Dispatched process  8
Time slot  13
	CPU 0: Put process  4 to run queue
	CPU 0: Dispatched process  4
	CPU 3: Put process  7 to run queue
	CPU 3: Dispatched process  7
libfree:241
print_pgtbl:
PID : 7
 PDG=7f00b4011e90 P4g=7f00ac000c30 PUD=7f00ac001c40 PMD=7f00ac002c50
	CPU 2: Put process  6 to run queue
	CPU 2: Dispatched process  5
Time slot  14
liballoc:218
print_pgtbl:
PID : 7
 PDG=7f00b4011e90 P4g=7f00ac000c30 PUD=7f00ac001c40 PMD=7f00ac002c50
	CPU 1: Put process  8 to run queue
	CPU 1: Dispatched process  8
Time slot  15
	CPU 0: Put process  4 to run queue
	CPU 0: Dispatched process  4
	CPU 3: Put process  7 to run queue
	CPU 3: Dispatched process  7
libfree:241
print_pgtbl:
PID : 7
 PDG=7f00b4011e90 P4g=7f00ac000c30 PUD=7f00ac001c40 PMD=7f00ac002c50
	CPU 2: Put process  5 to run queue
	CPU 2: Dispatched process  5
Time slot  16
libfree:241
print_pgtbl:
PID : 7
 PDG=7f00b4011e90 P4g=7f00ac000c30 PUD=7f00ac001c40 PMD=7f00ac002c50
Time slot  17
	CPU 1: Put process  8 to run queue
	CPU 1: Dispatched process  8
	CPU 0: Processed  4 has finished
	CPU 0: Dispatched process  6
	CPU 3: Processed  7 has finished
	CPU 3: Dispatched process  1
libread:406
print_pgtbl:
PID : 1
 PDG=7f00b4006ac0 P4g=7f00b0000c00 PUD=7f00b0001c10 PMD=7f00b0002c20
	CPU 2: Put process  5 to run queue
	CPU 2: Dispatched process  5
Time slot  18
	CPU 1: Put process  8 to run queue
	CPU 1: Dispatched process  8
Time slot  19
	CPU 0: Put process  6 to run queue
	CPU 0: Dispatched process  6
	CPU 3: Put process  1 to run queue
	CPU 3: Dispatched process  1
libfree:241
print_pgtbl:
PID : 1
 PDG=7f00b4006ac0 P4g=7f00b0000c00 PUD=7f00b0001c10 PMD=7f00b0002c20
	CPU 2: Put process  5 to run queue
	CPU 2: Dispatched process  5
Time slot  20
	CPU 2: Processed  5 has finished
	CPU 2 stopped
	CPU 1: Put process  8 to run queue
	CPU 1: Dispatched process  8
Time slot  21
	CPU 0: Put process  6 to run queue
	CPU 0: Dispatched process  6
	CPU 3: Processed  1 has finished
	CPU 3 stopped
Time slot  22
	CPU 1: Put process  8 to run queue
	CPU 1: Dispatched process  8
Time slot  23
	CPU 0: Put process  6 to run queue
	CPU 0: Dispatched process  6
Time slot  24
	CPU 1: Put process  8 to run queue
	CPU 1: Dispatched process  8
Time slot  25
	CPU 0: Put process  6 to run queue
	CPU 0: Dispatched process  6
Time slot  26
	CPU 1: Put process  8 to run queue
	CPU 1: Dispatched process  8
Time slot  27
	CPU 0: Processed  6 has finished
	CPU 0 stopped
Time slot  28
	CPU 1: Processed  8 has finished
	CPU 1 stopped
